Workbook

Sheet Data
A1: Published_Date | B1: City | C1: Crime_Type | D1: Accused | E1: Motive | F1: Method | G1: Deaths | H1: Injured | I1: Police_Action | J1: Victim_Details | K1: Summary | L1: Source_Name | M1: Source_URL | N1: Language | O1: City_Standard | P1: Crime_Category
A2: 45679 | B2: Karachi | C2: Honor Killing | D2: Fatima's father, Azhar | E2: So-called honour | F2: Shooting | G2: 2 | H2: 0 | I2: Arrested | J2: Fatima, teenage girl; Ali Solangi, 20 | K2: A teenage girl and her friend were shot dead in Karachi in an honor killing by the girl's father after discovering their relationship. | L2: Dawn News | M2: https://www.dawn.com/news/1886892 | N2: English | O2: Karachi | P2: Honor Killing
A3: 45667 | B3: Karachi | C3: Road Accident | D3: Water tanker driver | E3: Negligence | F3: Ran over by water tanker | G3: 2 | H3: 1 | I3: Report sought from Sindh Inspector General of Police | J3: 2 deceased, ages 57 and 49; 1 injured, age 30 | K3: Two people were killed and one injured when a water tanker ran over them on Shaheed-i-Millat Road in Karachi. The victims were taken to Jinnah Postgraduate Medical Centre. | L3: Dawn News | M3: https://www.dawn.com/news/1884293/2-killed-1-injured-in-water-tanker-accident-on-karachis-shaheed-i-millat-road-authorities | N3: English | O3: Karachi | P3: Accident / Hit & Run
A4: 45678 | B4: Karachi | C4: Robbery | D4: 3 armed robbers, 1 arrested suspect | E4: Not specified | F4: Shoot-out | G4: 2 | H4: 3 | I4: Police patrol arrived, 1 suspect arrested | J4: Jehanzeb Ibrahim, Subhan Ibrahim, Khurram, Muhammad Zubair | K4: Two suspected robbers were shot dead during a shoot-out with police in North Karachi, while three citizens were wounded. In a separate incident, a young man named Muhammad Zubair was shot dead in Gulshan-i-Iqbal. | L4: Dawn News | M4: https://www.dawn.com/news/1886644 | N4: English | O4: Karachi | P4: Robbery / Theft
A5: 45669 | B5: Karachi | C5: Murder | D5: Asma, Ghulam Nabi alias Deedar | E5: To get rid of her husband | F5: Strangulation and electrocution | G5: 1 | H5: 0 | I5: Court sentenced the accused | J5: Shah Zaman | K5: A sessions court sentenced Asma to life in prison for murdering her husband, Shah Zaman, with the help of co-accused Ghulam Nabi, who was sentenced to death. The murder was staged as a suicide. | L5: Dawn News | M5: https://www.dawn.com/news/1884601 | N5: English | O5: Karachi | P5: Murder
A6: 45680 | B6: Karachi | C6: Murder | D6: Rameez, accomplice | E6: Ransom | F6: Kidnapping and murder | G6: 1 | H6: 0 | I6: FIR registered, suspect arrested | J6: Iqbal Ahmed, 34M | K6: Iqbal Ahmed, who was kidnapped for ransom, was found murdered in his apartment. The police arrested a suspect who confessed to the crime. | L6: Dawn News | M6: https://www.dawn.com/news/1887063 | N6: English | O6: Karachi | P6: Murder
A7: 45675 | B7: Karachi | C7: Child Abduction and Murder | D7: Unknown | E7: Not specified | F7: Abduction and suspected homicide | G7: 1 | H7: 0 | I7: Investigation underway, body sent for postmortem, special investigation team formed | J7: Mohammed Sarim, 7 years old | K7: A seven-year-old boy, Mohammed Sarim, was found dead in a water tank after being missing for over a week. The police suspect foul play due to multiple injuries on the body, and investigations are ongoing. | L7: Dawn News | M7: https://www.dawn.com/news/1886087 | N7: English | O7: Karachi | P7: Child Abuse / Abduction
A8: 45668 | B8: Karachi | C8: Traffic Accident | D8: Shahzad Ali Shah (tanker driver) | E8: Rash driving | F8: Hit and run by water tanker | G8: 3 | H8: 1 | I8: Case registered against the tanker driver | J8: Syed Noman, Israr Ahmed, Saeed | K8: Three people were killed in two separate incidents involving water tankers in Karachi. The first incident involved an angry mob setting a tanker on fire after it hit two motorcyclists, while the second incident resulted in the death of a bike rider. | L8: Dawn News | M8: https://www.dawn.com/news/1884462 | N8: English | O8: Karachi | P8: Accident / Hit & Run
A9: 45682 | B9: Karachi | C9: Accidental Death | D9: Tariq Khan | F9: Car accident | G9: 1 | H9: 1 | I9: Investigation ongoing | J9: Danish, traffic marshal | K9: A track marshal named Danish was killed during the Hub Rally Autocross in Karachi when a car lost control and hit him, dragging him into a ditch. | L9: Dawn News | M9: https://www.dawn.com/news/1887608 | N9: English | O9: Karachi | P9: Accident / Hit & Run
A10: 45678 | B10: Karachi | C10: Child Abuse | D10: Teacher of the seminary | E10: Sexual assault | F10: Murder after sexual assault | G10: 1 | H10: 0 | I10: Suspect in custody, DNA samples being taken | J10: Mohammed Sarim, 7M | K10: The body of a seven-year-old boy, Mohammed Sarim, was found in a water tank after he went missing for 11 days. A post-mortem confirmed he was sexually assaulted before being killed, leading police to treat the case as murder. | L10: Dawn News | M10: https://www.dawn.com/news/1886645 | N10: English | O10: Karachi | P10: Child Abuse / Abduction
A11: 45672 | B11: Karachi | C11: Murder | D11: Uzair Baloch and his accomplices | E11: Not specified | F11: Police encounter | G11: 2 | H11: 0 | I11: Acquitted by court | J11: Constable Muhammad Asif, passer-by Nisar Ahmed | K11: Uzair Baloch, chief of the outlawed Peoples Amn Committee, was acquitted in a double murder case involving Constable Muhammad Asif and passer-by Nisar Ahmed due to lack of evidence. | L11: Dawn News | M11: https://www.dawn.com/news/1885190 | N11: English | O11: Karachi | P11: Murder
A12: 45658 | B12: Karachi | C12: Aerial Firing | D12: 75 suspects arrested | E12: Celebratory | F12: Aerial gunfire | G12: 0 | H12: 26 | I12: Further investigations underway | J12: Various ages and locations, including an 11-year-old boy and a 35-year-old male | K12: Aerial firing during New Year���s celebrations in Karachi injured 26 people, with 75 suspects arrested for celebratory gunfire. | L12: Dawn News | M12: https://www.dawn.com/news/1882435 | N12: English | O12: Karachi | P12: Assault / Firing
A13: 45680 | B13: Karachi | C13: Kidnapping/Murder | D13: Couple riding a motorcycle | E13: Sexual assault | F13: Kidnapping and murder | G13: 1 | H13: 0 | I13: Police treating the matter as a murder case, patrolling enhanced | J13: Third child, found dead in underground water tank | K13: Three children were kidnapped in Karachi, with one found dead after being sexually assaulted. Police are treating the case as a murder. | L13: Dawn News | M13: https://www.dawn.com/news/1887223 | N13: English | O13: Karachi | P13: Murder
A14: 45685 | B14: Sanghar | C14: Armed Assault | D14: MNA Allauddin Junejo and his armed men | E14: Land occupation | F14: Gunned down | G14: 3 | H14: 15 | I14: FIR not registered against MNA | J14: Mushtaq Junejo, Ali Baksh Junejo, Abdul Rasool Junejo | K14: Three men were killed and over a dozen injured in an armed assault in Sanghar. Protests erupted as police refused to name MNA Junejo in the FIR. | L14: Express Tribune | M14: https://tribune.com.pk/story/2524935/sanghar-police-accused-of-shielding-ppp-mna-in-triple-murder-case | N14: English | O14: Sanghar | P14: Assault / Firing
A15: 45667 | B15: Karachi | C15: Traffic Accident | D15: Driver of the tanker (fled the scene) | F15: Collision with motorcycles | G15: 2 | H15: 1 | I15: Investigation initiated | J15: Jamil, 44 years old; Muhammad Akbar, 30 years old | K15: Two motorcyclists were killed and one injured in a traffic accident on Shaheed-e-Millat Road when a water tanker collided with their motorcycles. The driver fled the scene. | L15: Express Tribune | M15: https://tribune.com.pk/story/2521246/water-tanker-crushes-two-motorcyclists-to-death-in-karachi | N15: English | O15: Karachi | P15: Accident / Hit & Run
A16: 45659 | B16: Lodhran | C16: Murder | D16: Unidentified assailant | E16: Not specified | F16: Shooting | G16: 1 | H16: 0 | I16: Case registered, investigation initiated | J16: Shakeel Ahmed, resident of Liaquatpur, Rahim Yar Khan | K16: A trailer driver, Shakeel Ahmed, was shot dead by an unidentified assailant in Lodhran while transporting goods from Karachi to Rawalpindi. Police have registered a case and are investigating the incident. | L16: Express Tribune | M16: https://tribune.com.pk/story/2519560/fugitive-killed-in-police-encounter | N16: English | O16: Lodhran | P16: Murder
A17: 45671 | B17: Swabi | C17: Honor Killing | D17: Husband | E17: Honor | F17: Shooting | G17: 2 | H17: 1 | I17: FIR registered | J17: 26-year-old woman | K17: A man allegedly killed his wife for honor and later died by suicide in Chota Lahor tehsil. The incident involved a shooting where the husband shot his wife and then himself. | L17: Dawn News | M17: https://www.dawn.com/news/1885068 | N17: English | O17: Swabi | P17: Honor Killing
A18: 45659 | B18: Bakr Jamali | C18: Honor Killing | D18: Husband of the victim | E18: Greed for money and property, claimed 'honour' | F18: Brutal murder | G18: 1 | H18: 0 | I18: Culprit arrested | J18: Young female lecturer and mother of three | K18: A young female lecturer was brutally murdered by her husband in an honor killing incident in Bakr Jamali, Sindh. The husband admitted to the crime, claiming it was out of 'honour', while the victim's family alleged greed for money and property. | L18: Dawn News | M18: https://www.dawn.com/news/1882572 | N18: English | O18: Bakr Jamali | P18: Honor Killing
A19: 45661 | B19: Peshawar | C19: Firing Incident | D19: Unidentified suspects | E19: Personal enmity over property and previous murders | F19: Exchange of fire | G19: 5 | H19: 6 | I19: Search for fleeing suspects | J19: People returning from a wedding ceremony | K19: Firing between two parties in Peshawar's Tehkal area resulted in five deaths and six injuries, stemming from personal enmity over property disputes. | L19: Dawn News | M19: https://www.dawn.com/news/1883049 | N19: English | O19: Peshawar | P19: Assault / Firing
A20: 45661 | B20: Turbat | C20: Terrorism | D20: Balochistan Liberation Army | E20: Terrorism | F20: Blast targeting a bus | G20: 4 | H20: 32 | I20: Investigations being conducted, area cordoned off by police and security forces | J20: Passengers on the bus, including SSP Zohaib Mohsin and his family | K20: A blast targeting a bus in Turbat resulted in 4 deaths and 32 injuries. The Balochistan Liberation Army claimed responsibility for the attack. | L20: Dawn News | M20: https://www.dawn.com/news/1883061 | N20: English | O20: Turbat | P20: Terrorism
A21: 45664 | B21: Islamabad | C21: Murder | D21: Unknown | E21: Not clear | F21: Found dead with injuries | G21: 1 | H21: 0 | I21: Body shifted to hospital | J21: Thomas Jurgen Bielefeld, 58, German diplomat | K21: A German diplomat, Thomas Jurgen Bielefeld, was found dead in his residence in Islamabad's Diplomatic Enclave with injuries. The police are investigating the circumstances surrounding his death. | L21: Dawn News | M21: https://www.dawn.com/news/1883542 | N21: English | O21: Islamabad | P21: Murder
A22: 45686 | B22: Sanghar | C22: Murder | D22: Salahuddin Junejo, Mohammed Khan Junejo, others | E22: Trespassing of cattle | F22: Gunfire | G22: 3 | H22: 19 | I22: FIR not registered | J22: Three members of Junejo community | K22: Three people were killed and 19 others injured in a clash between two groups over cattle trespassing in Sanghar. Protesters demand FIR against the accused, including a PPP lawmaker. | L22: Dawn News | M22: https://www.dawn.com/news/1888314 | N22: English | O22: Sanghar | P22: Murder
A23: 45675 | B23: Kurram | C23: Murder, Terrorism | D23: Unidentified militants | E23: Violations of peace agreement | F23: Ambush, IED blast | G23: 6 | H23: 7 | I23: Search operation launched, retaliatory action by security forces | J23: 4 drivers, identified as Imran, Hasan Ali, Shahid Ali; 1 FC soldier, Havildar Tasnim | K23: An ambush on a convoy in Lower Kurram resulted in the deaths of four drivers and two security officials, with several others injured. The attack was linked to ongoing tensions despite a peace agreement. | L23: Dawn News | M23: https://www.dawn.com/news/1885970 | N23: English | O23: Kurram | P23: Terrorism
A24: 45672 | B24: Karachi | C24: Murder | D24: Uzair Baloch, Jibrail, Hafeez Dada, Babar Punjabi, Zubair, Basir, Zahoor | E24: Not specified | F24: Shootout with police | G24: 2 | H24: 2 | I24: FIR lodged, acquitted by court | J24: Police officer Muhammad Asif, private individual Nisar Ahmed | K24: Uzair Baloch was acquitted in a case related to a police encounter that resulted in the deaths of two individuals in 2009. The court found insufficient evidence against him. | L24: The News International | M24: https://www.thenews.com.pk/print/1272309-uzair-baloch-acquitted-in-double-murder-case-for-want-of-evidence | N24: English | O24: Karachi | P24: Murder
A25: 45668 | B25: Mandi Bahauddin | C25: Explosion | D25: 2 people preparing fireworks | E25: Not specified | F25: Explosion due to short circuit | G25: 6 | H25: 7 | I25: Further investigation underway | J25: 6 deceased (1 man, 3 women, 2 girls), 7 injured (4 men, 3 women) | K25: An explosion at a firework warehouse in Mandi Bahauddin led to the roof of a house collapsing, resulting in 6 deaths and 7 injuries. | L25: Dawn News | M25: https://www.dawn.com/news/1884509 | N25: English | O25: Mandi Bahauddin | P25: Terrorism
A26: 45679 | B26: Islamabad | C26: Murder | D26: Iftikhar Ahmed, Muhammad Mustafa | E26: Police brutality | F26: Fatal shooting | G26: 1 | H26: 0 | I26: Death sentences reduced to life imprisonment | J26: Osama Satti, young man | K26: The Islamabad High Court reduced the death sentences of two police convicts in the Osama Satti murder case to life imprisonment while acquitting three others. Osama was fatally shot by police officers during an incident in January 2021. | L26: Express Tribune | M26: https://tribune.com.pk/story/2523749/ihc-reduces-death-penalties-to-life-imprisonment-in-osama-satti-case | N26: English | O26: Islamabad | P26: Murder
A27: 45687 | B27: North Waziristan | C27: Terrorism | D27: 6 khwarij (members of Tehreek-i-Taliban Pakistan) | E27: Terrorism | F27: Intelligence-based operation (IBO) | G27: 2 | H27: 0 | I27: Sanitisation operations conducted | J27: Major Hamza Israr, 29, Rawalpindi; Sepoy Muhammad Naeem, 26, Naseerabad | K27: Two soldiers were martyred and six terrorists were killed in an intelligence-based operation in North Waziristan. The operation targeted members of the banned Tehreek-i-Taliban Pakistan. | L27: Dawn News | M27: https://www.dawn.com/news/1888630 | N27: English | O27: North Waziristan | P27: Terrorism
... A57: 45682 | B57: Bahawalpur | C57: Kidnapping and Gang Rape | D57: Ishtiaq, Imran, Shehbaz | E57: Not specified | F57: Kidnapping and gang-rape | G57: 0 | H57: 0 | I57: Police raid conducted, victim recovered, case registered against accused | J57: Married woman, referred to as ���S��� | K57: A married woman was allegedly kidnapped by her relatives and sold to dacoits, where she was gang-raped. Police recovered her during a raid and handed her over to her family. | L57: Dawn News | M57: https://www.dawn.com/news/1887448 | N57: English | O57: Bahawalpur | P57: Rape / Sexual Assault
A58: 45675 | B58: Islamabad | C58: Corruption | D58: Imran Khan, Bushra Bibi, Malik Riaz | E58: Financial gain | F58: Misuse of authority, fraud | G58: 0 | H58: 0 | I58: Conviction announced | K58: Imran Khan and his wife Bushra Bibi were convicted in a corruption case involving the Al-Qadir Trust, with accusations of financial misconduct and misuse of authority. | L58: Dawn News | M58: https://www.dawn.com/news/1885973 | N58: English | O58: Islamabad | P58: Fraud / Corruption
A59: 45664 | B59: Khairpur | C59: Tribal Clash | D59: Armed men of Narejo tribe | E59: Tribal rivalry | F59: Open fire | G59: 2 | H59: 2 | I59: 119 criminals arrested in raids | K59: A tribal clash near Kalhora Kot resulted in the deaths of two individuals, Yameen Solangi and Sanaullah Solangi, due to gunfire from the Narejo tribe. The police have arrested 119 criminals in various operations. | L59: Express Tribune | M59: https://tribune.com.pk/story/2520501/ongoing-tribal-clashes-leave-two-more-dead | N59: English | O59: Khairpur | P59: Mob / Sectarian Violence
A60: 45674 | B60: Fateh Jang | C60: Robbery | D60: Hikmatullah, Sabit Khan, Milad Pasran Akhmat Gull | E60: Financial gain | F60: Snatching at gunpoint | G60: 0 | H60: 0 | I60: Case registered, suspects arrested, physical remand obtained | J60: Muhammad Bilal, citizen | K60: Police arrested three members of an Afghan gang involved in robbing citizens. The suspects snatched a mobile phone and Rs84,000 from the victim at gunpoint. | L60: Express Tribune | M60: https://tribune.com.pk/story/2522604/gang-of-afghan-bandits-busted | N60: English | O60: Fateh Jang | P60: Robbery / Theft
A61: 45684 | B61: Karachi | C61: Robbery | D61: Waqar Younas, Mubarak Shah | E61: Financial gain | F61: Forcibly covering heads and tying hands | G61: 0 | H61: 0 | I61: Case registered, suspects arrested, van seized, illegal weapons recovered | J61: Muhammad Ismail, livestock trader, Rs430,500 looted; Muhammad Anwar, passenger, Rs310,000 looted | K61: Saddar police arrested ringleader Waqar Younas and accomplice Mubarak Shah of a robbers' gang involved in looting passengers in a van. The suspects forcibly tied the victims and stole cash and a mobile phone. | L61: Express Tribune | M61: https://tribune.com.pk/story/2524709/two-netted-for-robbing-passengers | N61: English | O61: Karachi | P61: Robbery / Theft
A62: 45679 | B62: Karachi | C62: Robbery | D62: Mohammad Shariful Islam Shehzad | E62: Robbery | F62: Stabbing | G62: 0 | H62: 1 | I62: Suspect apprehended after a three-day manhunt | J62: Saif Ali Khan, actor | K62: Saif Ali Khan was attacked during a robbery attempt at his home, sustaining multiple stab wounds. He was rushed to the hospital by auto-rickshaw driver Bhajan Singh Rana, who responded to his distress call. | L62: Express Tribune | M62: https://tribune.com.pk/story/2523778/saif-ali-khan-poses-with-auto-driver-who-rushed-him-to-hospital | N62: English | O62: Karachi | P62: Robbery / Theft
A63: 45679 | B63: Karachi | C63: Terrorism | D63: Unidentified gunmen | E63: Sectarian tensions | F63: Rocket attack and abduction | G63: 6 | H63: 7 | I63: Operation against miscreants initiated | J63: Members of a convoy carrying essential items | K63: A convoy was attacked by unidentified gunmen near Bagan, resulting in the abduction of several individuals and the discovery of six dead bodies later. The authorities have launched an operation against the miscreants. | L63: Express Tribune | M63: https://tribune.com.pk/story/2523691/people-in-bagan-start-surrendering-firearms | N63: English | O63: Karachi | P63: Terrorism
A64: 45681 | B64: Karachi | C64: Violence during protest | D64: Sanan Khan Qureshi and 43 others | E64: Protest against Bahria Town Karachi | F64: Chanting anti-state slogans, resorting to violence, ransacking, torching private properties | G64: 0 | H64: 0 | I64: Two FIRs lodged, trial conducted | J64: Not specified | K64: An anti-terrorism court exonerated Sanan Khan Qureshi and 43 others from charges of violence during a protest against Bahria Town Karachi in 2021, citing lack of evidence. | L64: The News International | M64: https://www.thenews.com.pk/print/1275418-jsqm-leader-acquitted-in-bahria-town-violence-cases-for-lack-of-evidence | N64: English | O64: Karachi | P64: Mob / Sectarian Violence
A65: 45662 | B65: Muzaffargarh | C65: Robbery | D65: Unidentified robbers | E65: Robbery | F65: Shooting | G65: 1 | H65: 0 | I65: FIR registered, investigation underway | J65: Adil Gadi, trader | K65: A trader named Adil Gadi was shot dead by robbers near Noor Shah Talai when he resisted their demands for valuables. Local police have registered a case and are investigating the incident. | L65: The Nation | M65: https://www.nation.com.pk/05-Jan-2025/trader-shot-dead-for-resisting-robbery-in-muzaffargarh | N65: English | O65: Muzaffargarh | P65: Robbery / Theft
A66: 45674 | B66: Karachi | C66: Assault | D66: Jawad Ahmad and his men | E66: Power theft | F66: Thrashed officials and snatched faulty meter | G66: 0 | H66: 2 | I66: Application submitted for registration of a case, police asked to settle the issue | J66: Officials of Lahore Electric Supply Company (Lesco) | K66: Singer Jawad Ahmad and his men allegedly assaulted officials from Lesco after they detected power theft at a beauty salon owned by the singer's wife, leading to a request for police action. | L66: Dawn News | M66: https://images.dawn.com/news/1193148/legal-action-sought-after-jawad-ahmad-beats-harasses-lesco-staff-outside-wifes-salon | N66: English | O66: Karachi | P66: Assault / Firing
A67: 45687 | B67: Karachi | C67: Robbery | D67: Unidentified assailants | E67: Robbery | F67: Violent attack | G67: 0 | H67: 1 | I67: Investigation ongoing | J67: Saif Ali Khan, actor | K67: Saif Ali Khan was attacked at his home during an alleged robbery attempt, resulting in serious injuries that required immediate surgery. | L67: Express Tribune | M67: https://tribune.com.pk/story/2525476/karan-johar-announces-ibrahim-ali-khans-debut | N67: English | O67: Karachi | P67: Robbery / Theft
A68: 45671 | B68: Karachi | C68: Cryptocurrency Heist | D68: Eight suspects including police officers | E68: Financial gain | F68: Kidnapping and robbery | G68: 0 | H68: 0 | I68: Eight suspects arrested, investigation ongoing | J68: Muhammad Arsalan Malik, cryptocurrency trader | K68: Eight suspects, including police officers, were arrested in Karachi for a cryptocurrency heist worth over Rs90 million, involving the kidnapping of trader Muhammad Arsalan Malik. | L68: Express Tribune | M68: https://tribune.com.pk/story/2522025/eight-arrested-in-karachi-crypto-heist-rs129-million-recovered | N68: English | O68: Karachi | P68: Kidnapping
A69: 45658 | B69: Karachi | C69: Street Crime | D69: Ruthless street criminals | E69: Financial gain | F69: Robbery at gunpoint | G69: 106 | H69: 300 | I69: Police claimed a 21 percent reduction in crimes, but street crime continues to be a challenge | J69: Residents of Karachi, including women, children, and law-enforcement officials | K69: In 2024, Karachi experienced rampant street crime, resulting in 106 deaths and 300 injuries. Despite police claims of reduced crime rates, street criminals continued to operate with impunity, robbing residents of billions. | L69: The News International | M69: https://www.thenews.com.pk/print/1267450-karachi-saw-over-72-000-street-crime-incidents-in-2024 | N69: English | O69: Karachi | P69: Robbery / Theft
...

Sheet Analysis
A1: Crime News Analysis
A2: Total news (clean) | B2: =COUNTA(Data!$N$2:$N$20512) -> 20511 | C2: Repeat reports removed | D2: 436
A3: Exact duplicates removed | B3: 138
A4: News before duplicate removal | B4: =B2+B3+D2 -> 21085
A5: 1. News by Language
A6: Language | B6: News | C6: % of total
A7: Urdu | B7: =COUNTIF(Data!$N$2:$N$20512,A7) -> 15816 | C7: =B7/$B$2 -> 0.77109843
A8: English | B8: =COUNTIF(Data!$N$2:$N$20512,A8) -> 4695 | C8: =B8/$B$2 -> 0.22890157
A9: Total | B9: =SUM(B7:B8) -> 20511 | C9: =SUM(C7:C8) -> 1
A12: 2. Top 25 Cities by Number of News
A13: Rank | B13: City | C13: Total News | D13: Urdu | E13: English | F13: % of total
A14: 1 | B14: Lahore | C14: =COUNTIF(Data!$O$2:$O$20512,B14) -> 4038 | D14: =COUNTIFS(Data!$O$2:$O$20512,B14,Data!$N$2:$N$20512,"Urdu") -> 3510 | E14: =COUNTIFS(Data!$O$2:$O$20512,B14,Data!$N$2:$N$20512,"English") -> 528 | F14: =C14/$B$2 -> 0.19686997
A15: 2 | B15: Faisalabad | C15: =COUNTIF(Data!$O$2:$O$20512,B15) -> 2462 | D15: =COUNTIFS(Data!$O$2:$O$20512,B15,Data!$N$2:$N$20512,"Urdu") -> 2368 | E15: =COUNTIFS(Data!$O$2:$O$20512,B15,Data!$N$2:$N$20512,"English") -> 94 | F15: =C15/$B$2 -> 0.12003315
A16: 3 | B16: Karachi | C16: =COUNTIF(Data!$O$2:$O$20512,B16) -> 2376 | D16: =COUNTIFS(Data!$O$2:$O$20512,B16,Data!$N$2:$N$20512,"Urdu") -> 1427 | E16: =COUNTIFS(Data!$O$2:$O$20512,B16,Data!$N$2:$N$20512,"English") -> 949 | F16: =C16/$B$2 -> 0.11584028
A17: 4 | B17: Islamabad | C17: =COUNTIF(Data!$O$2:$O$20512,B17) -> 981 | D17: =COUNTIFS(Data!$O$2:$O$20512,B17,Data!$N$2:$N$20512,"Urdu") -> 555 | E17: =COUNTIFS(Data!$O$2:$O$20512,B17,Data!$N$2:$N$20512,"English") -> 426 | F17: =C17/$B$2 -> 0.047827995
A18: 5 | B18: Kasur | C18: =COUNTIF(Data!$O$2:$O$20512,B18) -> 871 | D18: =COUNTIFS(Data!$O$2:$O$20512,B18,Data!$N$2:$N$20512,"Urdu") -> 852 | E18: =COUNTIFS(Data!$O$2:$O$20512,B18,Data!$N$2:$N$20512,"English") -> 19 | F18: =C18/$B$2 -> 0.042465019
A19: 6 | B19: Kamoke | C19: =COUNTIF(Data!$O$2:$O$20512,B19) -> 609 | D19: =COUNTIFS(Data!$O$2:$O$20512,B19,Data!$N$2:$N$20512,"Urdu") -> 607 | E19: =COUNTIFS(Data!$O$2:$O$20512,B19,Data!$N$2:$N$20512,"English") -> 2 | F19: =C19/$B$2 -> 0.029691385
A20: 7 | B20: Rawalpindi | C20: =COUNTIF(Data!$O$2:$O$20512,B20) -> 533 | D20: =COUNTIFS(Data!$O$2:$O$20512,B20,Data!$N$2:$N$20512,"Urdu") -> 313 | E20: =COUNTIFS(Data!$O$2:$O$20512,B20,Data!$N$2:$N$20512,"English") -> 220 | F20: =C20/$B$2 -> 0.025986056
A21: 8 | B21: Ferozewala | C21: =COUNTIF(Data!$O$2:$O$20512,B21) -> 488 | D21: =COUNTIFS(Data!$O$2:$O$20512,B21,Data!$N$2:$N$20512,"Urdu") -> 488 | E21: =COUNTIFS(Data!$O$2:$O$20512,B21,Data!$N$2:$N$20512,"English") -> 0 | F21: =C21/$B$2 -> 0.023792112
A22: 9 | B22: Peshawar | C22: =COUNTIF(Data!$O$2:$O$20512,B22) -> 324 | D22: =COUNTIFS(Data!$O$2:$O$20512,B22,Data!$N$2:$N$20512,"Urdu") -> 192 | E22: =COUNTIFS(Data!$O$2:$O$20512,B22,Data!$N$2:$N$20512,"English") -> 132 | F22: =C22/$B$2 -> 0.015796402
A23: 10 | B23: Gujranwala | C23: =COUNTIF(Data!$O$2:$O$20512,B23) -> 314 | D23: =COUNTIFS(Data!$O$2:$O$20512,B23,Data!$N$2:$N$20512,"Urdu") -> 285 | E23: =COUNTIFS(Data!$O$2:$O$20512,B23,Data!$N$2:$N$20512,"English") -> 29 | F23: =C23/$B$2 -> 0.015308859
A24: 11 | B24: Quetta | C24: =COUNTIF(Data!$O$2:$O$20512,B24) -> 270 | D24: =COUNTIFS(Data!$O$2:$O$20512,B24,Data!$N$2:$N$20512,"Urdu") -> 122 | E24: =COUNTIFS(Data!$O$2:$O$20512,B24,Data!$N$2:$N$20512,"English") -> 148 | F24: =C24/$B$2 -> 0.013163668
A25: 12 | B25: Sialkot | C25: =COUNTIF(Data!$O$2:$O$20512,B25) -> 213 | D25: =COUNTIFS(Data!$O$2:$O$20512,B25,Data!$N$2:$N$20512,"Urdu") -> 179 | E25: =COUNTIFS(Data!$O$2:$O$20512,B25,Data!$N$2:$N$20512,"English") -> 34 | F25: =C25/$B$2 -> 0.010384672
... A38: 25 | B38: Gujrat | C38: =COUNTIF(Data!$O$2:$O$20512,B38) -> 89 | D38: =COUNTIFS(Data!$O$2:$O$20512,B38,Data!$N$2:$N$20512,"Urdu") -> 49 | E38: =COUNTIFS(Data!$O$2:$O$20512,B38,Data!$N$2:$N$20512,"English") -> 40 | F38: =C38/$B$2 -> 0.0043391351
B39: City Not Specified | C39: =COUNTIF(Data!$O$2:$O$20512,"Not Specified") -> 548
B40: Total Unique Cities / Areas | C40: 952
A43: 3. News by Crime Category
A44: Rank | B44: Crime Category | C44: Total News | D44: Urdu | E44: English | F44: % of total
A45: 1 | B45: Murder | C45: =COUNTIF(Data!$P$2:$P$20512,B45) -> 2876 | D45: =COUNTIFS(Data!$P$2:$P$20512,B45,Data!$N$2:$N$20512,"Urdu") -> 2150 | E45: =COUNTIFS(Data!$P$2:$P$20512,B45,Data!$N$2:$N$20512,"English") -> 726 | F45: =C45/$B$2 -> 0.14021744
A46: 2 | B46: Fraud / Corruption | C46: =COUNTIF(Data!$P$2:$P$20512,B46) -> 2747 | D46: =COUNTIFS(Data!$P$2:$P$20512,B46,Data!$N$2:$N$20512,"Urdu") -> 2358 | E46: =COUNTIFS(Data!$P$2:$P$20512,B46,Data!$N$2:$N$20512,"English") -> 389 | F46: =C46/$B$2 -> 0.13392814
A47: 3 | B47: Accident / Hit & Run | C47: =COUNTIF(Data!$P$2:$P$20512,B47) -> 1923 | D47: =COUNTIFS(Data!$P$2:$P$20512,B47,Data!$N$2:$N$20512,"Urdu") -> 1748 | E47: =COUNTIFS(Data!$P$2:$P$20512,B47,Data!$N$2:$N$20512,"English") -> 175 | F47: =C47/$B$2 -> 0.093754571
A48: 4 | B48: Terrorism | C48: =COUNTIF(Data!$P$2:$P$20512,B48) -> 1822 | D48: =COUNTIFS(Data!$P$2:$P$20512,B48,Data!$N$2:$N$20512,"Urdu") -> 692 | E48: =COUNTIFS(Data!$P$2:$P$20512,B48,Data!$N$2:$N$20512,"English") -> 1130 | F48: =C48/$B$2 -> 0.088830384
A49: 5 | B49: Rape / Sexual Assault | C49: =COUNTIF(Data!$P$2:$P$20512,B49) -> 1256 | D49: =COUNTIFS(Data!$P$2:$P$20512,B49,Data!$N$2:$N$20512,"Urdu") -> 1055 | E49: =COUNTIFS(Data!$P$2:$P$20512,B49,Data!$N$2:$N$20512,"English") -> 201 | F49: =C49/$B$2 -> 0.061235435
A50: 6 | B50: Drugs | C50: =COUNTIF(Data!$P$2:$P$20512,B50) -> 1184 | D50: =COUNTIFS(Data!$P$2:$P$20512,B50,Data!$N$2:$N$20512,"Urdu") -> 1045 | E50: =COUNTIFS(Data!$P$2:$P$20512,B50,Data!$N$2:$N$20512,"English") -> 139 | F50: =C50/$B$2 -> 0.057725123
A51: 7 | B51: Robbery / Theft | C51: =COUNTIF(Data!$P$2:$P$20512,B51) -> 1179 | D51: =COUNTIFS(Data!$P$2:$P$20512,B51,Data!$N$2:$N$20512,"Urdu") -> 948 | E51: =COUNTIFS(Data!$P$2:$P$20512,B51,Data!$N$2:$N$20512,"English") -> 231 | F51: =C51/$B$2 -> 0.057481351
A52: 8 | B52: Kidnapping | C52: =COUNTIF(Data!$P$2:$P$20512,B52) -> 1168 | D52: =COUNTIFS(Data!$P$2:$P$20512,B52,Data!$N$2:$N$20512,"Urdu") -> 978 | E52: =COUNTIFS(Data!$P$2:$P$20512,B52,Data!$N$2:$N$20512,"English") -> 190 | F52: =C52/$B$2 -> 0.056945054
A53: 9 | B53: Mob / Sectarian Violence | C53: =COUNTIF(Data!$P$2:$P$20512,B53) -> 709 | D53: =COUNTIFS(Data!$P$2:$P$20512,B53,Data!$N$2:$N$20512,"Urdu") -> 527 | E53: =COUNTIFS(Data!$P$2:$P$20512,B53,Data!$N$2:$N$20512,"English") -> 182 | F53: =C53/$B$2 -> 0.034566818
A54: 10 | B54: Illegal Weapons | C54: =COUNTIF(Data!$P$2:$P$20512,B54) -> 632 | D54: =COUNTIFS(Data!$P$2:$P$20512,B54,Data!$N$2:$N$20512,"Urdu") -> 610 | E54: =COUNTIFS(Data!$P$2:$P$20512,B54,Data!$N$2:$N$20512,"English") -> 22 | F54: =C54/$B$2 -> 0.030812735
A55: 11 | B55: Honor Killing | C55: =COUNTIF(Data!$P$2:$P$20512,B55) -> 598 | D55: =COUNTIFS(Data!$P$2:$P$20512,B55,Data!$N$2:$N$20512,"Urdu") -> 511 | E55: =COUNTIFS(Data!$P$2:$P$20512,B55,Data!$N$2:$N$20512,"English") -> 87 | F55: =C55/$B$2 -> 0.029155088
A56: 12 | B56: Cybercrime | C56: =COUNTIF(Data!$P$2:$P$20512,B56) -> 530 | D56: =COUNTIFS(Data!$P$2:$P$20512,B56,Data!$N$2:$N$20512,"Urdu") -> 383 | E56: =COUNTIFS(Data!$P$2:$P$20512,B56,Data!$N$2:$N$20512,"English") -> 147 | F56: =C56/$B$2 -> 0.025839793
...
